<?xml version="1.0" encoding="utf-8"?>
<!-- This URDF was automatically created by SolidWorks to URDF Exporter! Originally created by Stephen Brawner (brawner@gmail.com) 
     Commit Version: 1.5.1-0-g916b5db  Build Version: 1.5.7152.31018
     For more information, please see http://wiki.ros.org/sw_urdf_exporter -->
<robot
  name="grey">
  <link
    name="base_link">
    <inertial>
      <origin
        xyz="-2.084E-17 0.077012 0.015854"
        rpy="0 0 0" />
      <mass
        value="2.0286" />
      <inertia
        ixx="0.02636"
        ixy="-3.704E-19"
        ixz="-1.323E-18"
        iyy="0.049356"
        iyz="0.0010919"
        izz="0.024274" />
    </inertial>
    <visual>
      <origin
        xyz="0 0 0"
        rpy="0 0 0" />
      <geometry>
        <mesh
          filename="package://grey/meshes/base_link.STL" />
      </geometry>
      <material
        name="">
        <color
          rgba="0.79216 0.81961 0.93333 1" />
      </material>
    </visual>
    <collision>
      <origin
        xyz="0 0 0"
        rpy="0 0 0" />
      <geometry>
        <mesh
          filename="package://grey/meshes/base_link.STL" />
      </geometry>
    </collision>
  </link>
  <link
    name="left_wheel">
    <inertial>
      <origin
        xyz="0.057772 0 0"
        rpy="0 0 0" />
      <mass
        value="0.67732" />
      <inertia
        ixx="0.00081812"
        ixy="-1.5659E-20"
        ixz="-1.7435E-20"
        iyy="0.00048728"
        iyz="-1.8261E-05"
        izz="0.00048728" />
    </inertial>
    <visual>
      <origin
        xyz="0 0 0"
        rpy="0 0 0" />
      <geometry>
        <mesh
          filename="package://grey/meshes/left_wheel.STL" />
      </geometry>
      <material
        name="">
        <color
          rgba="0.79216 0.81961 0.93333 1" />
      </material>
    </visual>
    <collision>
      <origin
        xyz="0 0 0"
        rpy="0 0 0" />
      <geometry>
        <mesh
          filename="package://grey/meshes/left_wheel.STL" />
      </geometry>
    </collision>
  </link>
  <joint
    name="left_wheel_joint"
    type="continuous">
    <origin
      xyz="0.163 0.07 0.05"
      rpy="1.5708 0 0" />
    <parent
      link="base_link" />
    <child
      link="left_wheel" />
    <axis
      xyz="1 0 0" />
    <dynamics
      damping="1"
      friction="5" />
  </joint>
  <link
    name="right_wheel">
    <inertial>
      <origin
        xyz="0.057772 -1.3878E-17 0"
        rpy="0 0 0" />
      <mass
        value="0.67732" />
      <inertia
        ixx="0.00081812"
        ixy="-3.3374E-20"
        ixz="2.7561E-20"
        iyy="0.00048728"
        iyz="-1.8261E-05"
        izz="0.00048728" />
    </inertial>
    <visual>
      <origin
        xyz="0 0 0"
        rpy="0 0 0" />
      <geometry>
        <mesh
          filename="package://grey/meshes/right_wheel.STL" />
      </geometry>
      <material
        name="">
        <color
          rgba="0.79216 0.81961 0.93333 1" />
      </material>
    </visual>
    <collision>
      <origin
        xyz="0 0 0"
        rpy="0 0 0" />
      <geometry>
        <mesh
          filename="package://grey/meshes/right_wheel.STL" />
      </geometry>
    </collision>
  </link>
  <joint
    name="right_wheel_joint"
    type="continuous">
    <origin
      xyz="-0.163 0.07 0.05"
      rpy="1.9487 0 3.1416" />
    <parent
      link="base_link" />
    <child
      link="right_wheel" />
    <axis
      xyz="1 0 0" />
    <dynamics
      damping="1"
      friction="5" />
  </joint>
</robot>